Workbook

Sheet Mal hereket
D1: Anbar adı | E1: Miqdar
D2: Astara | E2: Astara | F2: Ələt | G2: Ələt | H2: Xocahəsən | I2: Xocahəsən
A3: Malın kodu | B3: Malın adı | C3: Kontragentin / Layihənin adı | D3: Giriş | E3: Çıxış | F3: Giriş | G3: Çıxış | H3: Giriş | I3: Çıxış
A4: 0000001 | B4: Filtr/ yağ/ ZP3375 MG/ "FİL"/Türkiyə istehsalı | C4: Əvvələ anbar qalığı | F4: 1 | G4: 0
A5: 0000002 | B5: Filtr/ yağ/ ZP520/ "FİL"/Türkiyə istehsalı | C5: Əvvələ anbar qalığı | F5: 1 | G5: 0
A6: 0000003 | B6: Kabel qoruyucu gövdə / alüminium / kontaktor üçün | C6: Əvvələ anbar qalığı | F6: 17 | G6: 0
A7: 0000004 | B7: Gərginlik sabitləşdiricisi / 1 faza / "ANDELİ" / SVC-200000VA | C7: Əvvələ anbar qalığı | F7: 1 | G7: 0
A8: 0000005 | B8: Elektrik lövhə / 550x800mm / metal | C8: Əvvələ anbar qalığı | F8: 1 | G8: 0
A9: 0000006 | B9: Kabel qoruyucu gövdə / alüminium / kontaktor ilə | C9: Əvvələ anbar qalığı | F9: 6 | G9: 0
A10: 0000007 | B10: Filtr/ yağ/ ZP540 A/ "FİL"/Türkiyə istehsalı | C10: Əvvələ anbar qalığı | F10: 1 | G10: 0
A11: 0000008 | B11: Laboratoriya sınaq qabları / podnos tipli / paslanmaz metal | C11: Əvvələ anbar qalığı | F11: 12 | G11: 0
A12: 0000009 | B12: Laboratoriya sınaq qabları / kolba / plastik | C12: Əvvələ anbar qalığı | F12: 1 | G12: 0
A13: 0000010 | B13: Filtr/ yanacaq/ PL 270 / "SCT" / Turbomax | C13: Əvvələ anbar qalığı | F13: 1 | G13: 0
A14: 0000011 | B14: Filtr/ yanacaq/ ZP3043 FMB/ "FİL"/Türkiyə istehsalı | C14: Əvvələ anbar qalığı | F14: 2 | G14: 0
A15: 0000012 | B15: Filtr/ yağ/ ZP531/ "FİL"/Türkiyə istehsalı | C15: Əvvələ anbar qalığı | F15: 1 | G15: 0
... A61: 0000058 | B61: Filtr/ hava/ AF 1822/ "TUC"/ Çin istehsalı | C61: Əvvələ anbar qalığı | F61: 2 | G61: 0
A62: 0000059 | B62: Filtr/ hava/ SHF 365/ "TUC"/ Çin istehsalı | C62: Ələt anbar | H62: 1 | I62: 0
A63: 0000059 | B63: Filtr/ hava/ SHF 365/ "TUC"/ Çin istehsalı | C63: Əvvələ anbar qalığı | F63: 1 | G63: 0
A64: 0000059 | B64: Filtr/ hava/ SHF 365/ "TUC"/ Çin istehsalı | C64: Xocahəsən anbar | F64: 0 | G64: 1
A65: 0000060 | B65: Filtr/ hava/ C13103/ "TUC"/ Çin istehsalı | C65: Əvvələ anbar qalığı | F65: 1 | G65: 0
A66: 0000061 | B66: Filtr/ yanacaq/ 6754-71-6140/ "Komatsu"/ Yaponiya istehsalı | C66: Əvvələ anbar qalığı | F66: 1 | G66: 0
A67: 0000062 | B67: Filtr/ yanacaq/ FC-1003/ "Sakura"/ İndoneziya istehsalı | C67: Əvvələ anbar qalığı | F67: 4 | G67: 0
A68: 0000063 | B68: Filtr/ yağ/ P554403/ "Donaldson"/ Meksika istehsalı | C68: Əvvələ anbar qalığı | F68: 5 | G68: 0
A69: 0000064 | B69: Filtr/ yağ/ SP450/ "Asas"/ Türkiyə istehsalı | C69: Əvvələ anbar qalığı | F69: 3 | G69: 0
A70: 0000065 | B70: Filtr/ hidravlik/ P550148/ "Donaldson"/ İtaliya istehsalı | C70: Əvvələ anbar qalığı | F70: 1 | G70: 0
A71: 0000066 | B71: Filtr/ yanacaq/ P551315/ "Donaldson"/ ABŞ istehsalı | C71: Əvvələ anbar qalığı | F71: 1 | G71: 0
A72: 0000067 | B72: Filtr/ yağ/ P550008/ "Donaldson"/ ABŞ istehsalı | C72: Əvvələ anbar qalığı | F72: 1 | G72: 0
A73: 0000068 | B73: Filtr/ yağ/ ZP 3375 MG/ "Fil"/ Türkiyə istehsalı | C73: Əvvələ anbar qalığı | F73: 1 | G73: 0
A74: 0000069 | B74: Filtr/ yağ/ DS 1169/ "Delsa"/ Türkiyə istehsalı | C74: Əvvələ anbar qalığı | F74: 1 | G74: 0
... A136: 0000131 | B136: Gərginlik tənzimləyicisi (Stabilizator) / 20 kVt / "Andeli" / SVC-2000 VA / Çin istehsalı | C136: Əvvələ anbar qalığı | F136: 1 | G136: 0
A137: 0000132 | B137: Printer / "HP" / MFP M181FW / Vyetnam istehsalı | C137: Ələt anbar | H137: 1 | I137: 0
A138: 0000132 | B138: Printer / "HP" / MFP M181FW / Vyetnam istehsalı | C138: Əvvələ anbar qalığı | F138: 1 | G138: 0
A139: 0000132 | B139: Printer / "HP" / MFP M181FW / Vyetnam istehsalı | C139: Xocahəsən anbar | F139: 0 | G139: 1
A140: 0000133 | B140: Elektrik mişar / 2350 Wt / d 235 mm / "Viktor" / Çin istehsalı | C140: Ələt anbar | H140: 1 | I140: 0
A141: 0000133 | B141: Elektrik mişar / 2350 Wt / d 235 mm / "Viktor" / Çin istehsalı | C141: Əvvələ anbar qalığı | F141: 1 | G141: 0
A142: 0000133 | B142: Elektrik mişar / 2350 Wt / d 235 mm / "Viktor" / Çin istehsalı | C142: Xocahəsən anbar | F142: 0 | G142: 1
A143: 0000134 | B143: Perforator / "Bosch" / GBH 11 DE / Almaniya istehsalı | C143: Əvvələ anbar qalığı | F143: 1 | G143: 0
A144: 0000135 | B144: Pika / 25 x 400 mm / pnevmatik çəkic üçün / Çin istehsalı | C144: Ələt anbar | H144: 4 | I144: 0
A145: 0000135 | B145: Pika / 25 x 400 mm / pnevmatik çəkic üçün / Çin istehsalı | C145: Əvvələ anbar qalığı | F145: 8 | G145: 0
A146: 0000135 | B146: Pika / 25 x 400 mm / pnevmatik çəkic üçün / Çin istehsalı | C146: Xocahəsən anbar | F146: 0 | G146: 4
...

Sheet Checkup
A1: Mal adları | B1: Fərq
A2: Açar / 6 künc / d 12 mm | B2: 0
A3: Açar / qayka / 19 x 22 | B3: 0
A4: Açar / qayka / 22 x 24 | B4: 0
A5: Açar / qayka / bir tərəfi halqalı / 28 | B5: 0
A6: Açar / qayka / bir tərəfi halqalı / 30 | B6: 0
A7: Açar / qayka / bir tərəfi halqalı / 32 | B7: 0
A8: Açar / qayka / halqalı / 27 | B8: 0
A9: Açar / qayka / halqalı / 36 | B9: 0
A10: Açar / qayka / halqalı / 41 | B10: 0
A11: Açar / qayka / iki tərəfi halqalı / 30 x 32 | B11: 0
A12: Açar / qayka / iki tərəfi halqalı / 36 x 41 | B12: 0
A13: Açar başlığı / 15 mm | B13: 0
... A888: Yol nişanı / sürət 10 km/s | B888: 0
A889: (blank)
A890: Mouse-Keyboard / wireless / "DELL" KM3322W | B890: 0
A891: Notebook / 16GB / 512GB / SSD 6GB / "HP" VİCTUS 15-FA2082 WM i5-1342OH | B891: 0
A892: Çanta / notebook üçün / "HP" Prelude 15.6" TOP LOAD | B892: 0
A893: Sayğac / Elektrik / 3*100A LUN23 /LUNA | B893: 0
A894: Çəkmə / qısa boğaz / 44 / "YDS" | B894: 0
A895: Çəkmə / qısa boğaz / 42 / "YDS" | B895: 0
A896: Laqonda / 180/230/2000Vt / "Dingoi" / JB02401 | B896: 0
A897: Ayaqqabı / qısa boğaz / 42 / "Dingoi" 90050142 | B897: 0
A898: Laqonda / 125/1220V / "Dingoi" / 101090 | B898: 0
A899: Eynək / qara / 3M358 | B899: 0
A900: Disk / kəsici / d 230 mm / 3.2 / laqonda üçün / "Grassland" | B900: 0
A901: Jilet / sarı-narıncı / briqadir üçün | B901: 0
... A1227: Grand Total | B1227: 0

Sheet Filtrasiya
B3: № | C3: Tarix | D3: Malın adı | E3: Malın kodu | F3: Ölçü vahidi | G3: Malın miqdarı | H3: Vahidin qiyməti | I3: Ümumi məbləğ | J3: Alınma üsulu | K3: Kontragentin adı | L3: Müqavilə nömrəsi | M3: Qaimə №
B4: =ROW()-3 -> 1 | C4: 46148 | D4: {=_xlfn.XLOOKUP(Table4[[#This Row],[Malın kodu]],Table1[[#All],[Malın kodu]],Table1[[#All],[Malın adı]],"xəta",0)} -> Fırça / N143 (şotka pas qara) | E4: 0000997 | F4: ədəd | G4: 3 | H4: 1 | I4: =Table4[[#This Row],[Malın miqdarı]]*Table4[[#This Row],[Vahidin qiyməti]] -> 3 | J4: Köçürmə | K4: "Neq MMC" | L4: № 24-060 | M4: 3403
B5: =ROW()-3 -> 2 | C5: 46148 | D5: {=_xlfn.XLOOKUP(Table4[[#This Row],[Malın kodu]],Table1[[#All],[Malın kodu]],Table1[[#All],[Malın adı]],"xəta",0)} -> Bıçaq / oboy / N115 | E5: 0001038 | F5: ədəd | G5: 2 | H5: 1.2 | I5: =Table4[[#This Row],[Malın miqdarı]]*Table4[[#This Row],[Vahidin qiyməti]] -> 2.4 | J5: Köçürmə | K5: "Neq MMC" | L5: № 24-060 | M5: 3403
B6: =ROW()-3 -> 3 | C6: 46148 | D6: {=_xlfn.XLOOKUP(Table4[[#This Row],[Malın kodu]],Table1[[#All],[Malın kodu]],Table1[[#All],[Malın adı]],"xəta",0)} -> Qıfıl / VAZ | E6: 0001039 | F6: ədəd | G6: 3 | H6: 4.5 | I6: =Table4[[#This Row],[Malın miqdarı]]*Table4[[#This Row],[Vahidin qiyməti]] -> 13.5 | J6: Köçürmə | K6: "Neq MMC" | L6: № 24-060 | M6: 3403
B7: =ROW()-3 -> 4 | C7: 46148 | D7: {=_xlfn.XLOOKUP(Table4[[#This Row],[Malın kodu]],Table1[[#All],[Malın kodu]],Table1[[#All],[Malın adı]],"xəta",0)} -> Qıfıl / Extra 70 | E7: 0001040 | F7: ədəd | G7: 2 | H7: 2.2 | I7: =Table4[[#This Row],[Malın miqdarı]]*Table4[[#This Row],[Vahidin qiyməti]] -> 4.4 | J7: Köçürmə | K7: "Neq MMC" | L7: № 24-060 | M7: 3403
B8: =ROW()-3 -> 5 | C8: 46148 | D8: {=_xlfn.XLOOKUP(Table4[[#This Row],[Malın kodu]],Table1[[#All],[Malın kodu]],Table1[[#All],[Malın adı]],"xəta",0)} -> Projektor / led / 200 Vt | E8: 0001041 | F8: ədəd | G8: 3 | H8: 30 | I8: =Table4[[#This Row],[Malın miqdarı]]*Table4[[#This Row],[Vahidin qiyməti]] -> 90 | J8: Köçürmə | K8: "Neq MMC" | L8: № 24-060 | M8: 3403
B9: =ROW()-3 -> 6 | C9: 46148 | D9: {=_xlfn.XLOOKUP(Table4[[#This Row],[Malın kodu]],Table1[[#All],[Malın kodu]],Table1[[#All],[Malın adı]],"xəta",0)} -> Lampa / 12 Vt / ağ / kürəvi | E9: 0001042 | F9: ədəd | G9: 10 | H9: 1.2 | I9: =Table4[[#This Row],[Malın miqdarı]]*Table4[[#This Row],[Vahidin qiyməti]] -> 12 | J9: Köçürmə | K9: "Neq MMC" | L9: № 24-060 | M9: 3403
B10: =ROW()-3 -> 7 | C10: 46148 | D10: {=_xlfn.XLOOKUP(Table4[[#This Row],[Malın kodu]],Table1[[#All],[Malın kodu]],Table1[[#All],[Malın adı]],"xəta",0)} -> Əlcək / göy | E10: 0001043 | F10: ədəd | G10: 2 | H10: 5 | I10: =Table4[[#This Row],[Malın miqdarı]]*Table4[[#This Row],[Vahidin qiyməti]] -> 10 | J10: Köçürmə | K10: "Neq MMC" | L10: № 24-060 | M10: 3403
B11: =ROW()-3 -> 8 | C11: 46148 | D11: {=_xlfn.XLOOKUP(Table4[[#This Row],[Malın kodu]],Table1[[#All],[Malın kodu]],Table1[[#All],[Malın adı]],"xəta",0)} -> Metrə / 10m / "Fisko" / N88 | E11: 0001044 | F11: ədəd | G11: 1 | H11: 3 | I11: =Table4[[#This Row],[Malın miqdarı]]*Table4[[#This Row],[Vahidin qiyməti]] -> 3 | J11: Köçürmə | K11: "Neq MMC" | L11: № 24-060 | M11: 3403
B12: =ROW()-3 -> 9 | C12: 46148 | D12: {=_xlfn.XLOOKUP(Table4[[#This Row],[Malın kodu]],Table1[[#All],[Malın kodu]],Table1[[#All],[Malın adı]],"xəta",0)} -> Araba təkəri | E12: 0001045 | F12: ədəd | G12: 1 | H12: 5 | I12: =Table4[[#This Row],[Malın miqdarı]]*Table4[[#This Row],[Vahidin qiyməti]] -> 5 | J12: Köçürmə | K12: "Neq MMC" | L12: № 24-060 | M12: 3403
B13: =ROW()-3 -> 10 | C13: 46148 | D13: {=_xlfn.XLOOKUP(Table4[[#This Row],[Malın kodu]],Table1[[#All],[Malın kodu]],Table1[[#All],[Malın adı]],"xəta",0)} -> Kömür / laqonda üçün / "Conan" | E13: 0001046 | F13: ədəd | G13: 1 | H13: 5.5 | I13: =Table4[[#This Row],[Malın miqdarı]]*Table4[[#This Row],[Vahidin qiyməti]] -> 5.5 | J13: Köçürmə | K13: "Neq MMC" | L13: № 24-060 | M13: 3403
B14: =ROW()-3 -> 11 | C14: 46149 | D14: {=_xlfn.XLOOKUP(Table4[[#This Row],[Malın kodu]],Table1[[#All],[Malın kodu]],Table1[[#All],[Malın adı]],"xəta",0)} -> Potric uzatma prizi / 5x32A / 225 | E14: 0001054 | F14: ədəd | G14: 20 | H14: 5.5 | I14: =Table4[[#This Row],[Malın miqdarı]]*Table4[[#This Row],[Vahidin qiyməti]] -> 110 | J14: Köçürmə | K14: "Amper Elektrik" | L14: №198AMP/2026. | M14: 22429
B15: =ROW()-3 -> 12 | C15: 46149 | D15: {=_xlfn.XLOOKUP(Table4[[#This Row],[Malın kodu]],Table1[[#All],[Malın kodu]],Table1[[#All],[Malın adı]],"xəta",0)} -> MİQRİK XCK-J108 POTRİC | E15: 0001055 | F15: ədəd | G15: 4 | H15: 12 | I15: =Table4[[#This Row],[Malın miqdarı]]*Table4[[#This Row],[Vahidin qiyməti]] -> 48 | J15: Köçürmə | K15: "Amper Elektrik" | L15: №198AMP/2026. | M15: 22429
... B22: =ROW()-3 -> 19 | C22: 46149 | D22: {=_xlfn.XLOOKUP(Table4[[#This Row],[Malın kodu]],Table1[[#All],[Malın kodu]],Table1[[#All],[Malın adı]],"xəta",0)} -> Potric / 5x32A / FİŞ 025 | E22: 0001062 | F22: ədəd | G22: 20 | H22: 5.9 | I22: =Table4[[#This Row],[Malın miqdarı]]*Table4[[#This Row],[Vahidin qiyməti]] -> 118 | J22: Köçürmə | K22: "Amper Elektrik" | L22: №198AMP/2026. | M22: 22429
B23: =ROW()-3 -> 20 | C23: 46174 | D23: {=_xlfn.XLOOKUP(Table4[[#This Row],[Malın kodu]],Table1[[#All],[Malın kodu]],Table1[[#All],[Malın adı]],"xəta",0)} -> Filtr/ yağ/ ZP3375 MG/ "FİL"/Türkiyə istehsalı | E23: 0000001 | F23: ədəd | G23: 1 | I23: =Table4[[#This Row],[Malın miqdarı]]*Table4[[#This Row],[Vahidin qiyməti]] -> 0 | J23: Əvvələ qalıq | K23: Anbar qalığı | L23: =_xlfn.XLOOKUP(Table4[[#This Row],[Kontragentin adı]],Table2[Kontragentin adı],Table2[Müqavilə nömrəsi],"Xəta",0) -> 0 | M23: =_xlfn.XLOOKUP(Table4[[#This Row],[Kontragentin adı]],Table2[Kontragentin adı],Table2[Müqavilə nömrəsi],"Xəta",0) -> 0
B24: =ROW()-3 -> 21 | C24: 46174 | D24: {=_xlfn.XLOOKUP(Table4[[#This Row],[Malın kodu]],Table1[[#All],[Malın kodu]],Table1[[#All],[Malın adı]],"xəta",0)} -> Filtr/ yağ/ ZP520/ "FİL"/Türkiyə istehsalı | E24: 0000002 | F24: ədəd | G24: 1 | I24: =Table4[[#This Row],[Malın miqdarı]]*Table4[[#This Row],[Vahidin qiyməti]] -> 0 | J24: Əvvələ qalıq | K24: Anbar qalığı | L24: =_xlfn.XLOOKUP(Table4[[#This Row],[Kontragentin adı]],Table2[Kontragentin adı],Table2[Müqavilə nömrəsi],"Xəta",0) -> 0 | M24: =_xlfn.XLOOKUP(Table4[[#This Row],[Kontragentin adı]],Table2[Kontragentin adı],Table2[Müqavilə nömrəsi],"Xəta",0) -> 0
B25: =ROW()-3 -> 22 | C25: 46174 | D25: {=_xlfn.XLOOKUP(Table4[[#This Row],[Malın kodu]],Table1[[#All],[Malın kodu]],Table1[[#All],[Malın adı]],"xəta",0)} -> Kabel qoruyucu gövdə / alüminium / kontaktor üçün | E25: 0000003 | F25: ədəd | G25: 17 | I25: =Table4[[#This Row],[Malın miqdarı]]*Table4[[#This Row],[Vahidin qiyməti]] -> 0 | J25: Əvvələ qalıq | K25: Anbar qalığı | L25: =_xlfn.XLOOKUP(Table4[[#This Row],[Kontragentin adı]],Table2[Kontragentin adı],Table2[Müqavilə nömrəsi],"Xəta",0) -> 0 | M25: =_xlfn.XLOOKUP(Table4[[#This Row],[Kontragentin adı]],Table2[Kontragentin adı],Table2[Müqavilə nömrəsi],"Xəta",0) -> 0
B26: =ROW()-3 -> 23 | C26: 46174 | D26: {=_xlfn.XLOOKUP(Table4[[#This Row],[Malın kodu]],Table1[[#All],[Malın kodu]],Table1[[#All],[Malın adı]],"xəta",0)} -> Gərginlik sabitləşdiricisi / 1 faza / "ANDELİ" / SVC-200000VA | E26: 0000004 | F26: ədəd | G26: 1 | I26: =Table4[[#This Row],[Malın miqdarı]]*Table4[[#This Row],[Vahidin qiyməti]] -> 0 | J26: Əvvələ qalıq | K26: Anbar qalığı | L26: =_xlfn.XLOOKUP(Table4[[#This Row],[Kontragentin adı]],Table2[Kontragentin adı],Table2[Müqavilə nömrəsi],"Xəta",0) -> 0 | M26: =_xlfn.XLOOKUP(Table4[[#This Row],[Kontragentin adı]],Table2[Kontragentin adı],Table2[Müqavilə nömrəsi],"Xəta",0) -> 0
B27: =ROW()-3 -> 24 | C27: 46174 | D27: {=_xlfn.XLOOKUP(Table4[[#This Row],[Malın kodu]],Table1[[#All],[Malın kodu]],Table1[[#All],[Malın adı]],"xəta",0)} -> Elektrik lövhə / 550x800mm / metal | E27: 0000005 | F27: ədəd | G27: 1 | I27: =Table4[[#This Row],[Malın miqdarı]]*Table4[[#This Row],[Vahidin qiyməti]] -> 0 | J27: Əvvələ qalıq | K27: Anbar qalığı | L27: =_xlfn.XLOOKUP(Table4[[#This Row],[Kontragentin adı]],Table2[Kontragentin adı],Table2[Müqavilə nömrəsi],"Xəta",0) -> 0 | M27: =_xlfn.XLOOKUP(Table4[[#This Row],[Kontragentin adı]],Table2[Kontragentin adı],Table2[Müqavilə nömrəsi],"Xəta",0) -> 0
B28: =ROW()-3 -> 25 | C28: 46174 | D28: {=_xlfn.XLOOKUP(Table4[[#This Row],[Malın kodu]],Table1[[#All],[Malın kodu]],Table1[[#All],[Malın adı]],"xəta",0)} -> Kabel qoruyucu gövdə / alüminium / kontaktor ilə | E28: 0000006 | F28: dəst | G28: 6 | I28: =Table4[[#This Row],[Malın miqdarı]]*Table4[[#This Row],[Vahidin qiyməti]] -> 0 | J28: Əvvələ qalıq | K28: Anbar qalığı | L28: =_xlfn.XLOOKUP(Table4[[#This Row],[Kontragentin adı]],Table2[Kontragentin adı],Table2[Müqavilə nömrəsi],"Xəta",0) -> 0 | M28: =_xlfn.XLOOKUP(Table4[[#This Row],[Kontragentin adı]],Table2[Kontragentin adı],Table2[Müqavilə nömrəsi],"Xəta",0) -> 0
B29: =ROW()-3 -> 26 | C29: 46174 | D29: {=_xlfn.XLOOKUP(Table4[[#This Row],[Malın kodu]],Table1[[#All],[Malın kodu]],Table1[[#All],[Malın adı]],"xəta",0)} -> Filtr/ yağ/ ZP540 A/ "FİL"/Türkiyə istehsalı | E29: 0000007 | F29: ədəd | G29: 1 | I29: =Table4[[#This Row],[Malın miqdarı]]*Table4[[#This Row],[Vahidin qiyməti]] -> 0 | J29: Əvvələ qalıq | K29: Anbar qalığı | L29: =_xlfn.XLOOKUP(Table4[[#This Row],[Kontragentin adı]],Table2[Kontragentin adı],Table2[Müqavilə nömrəsi],"Xəta",0) -> 0 | M29: =_xlfn.XLOOKUP(Table4[[#This Row],[Kontragentin adı]],Table2[Kontragentin adı],Table2[Müqavilə nömrəsi],"Xəta",0) -> 0
B30: =ROW()-3 -> 27 | C30: 46174 | D30: {=_xlfn.XLOOKUP(Table4[[#This Row],[Malın kodu]],Table1[[#All],[Malın kodu]],Table1[[#All],[Malın adı]],"xəta",0)} -> Laboratoriya sınaq qabları / podnos tipli / paslanmaz metal | E30: 0000008 | F30: ədəd | G30: 12 | I30: =Table4[[#This Row],[Malın miqdarı]]*Table4[[#This Row],[Vahidin qiyməti]] -> 0 | J30: Əvvələ qalıq | K30: Anbar qalığı | L30: =_xlfn.XLOOKUP(Table4[[#This Row],[Kontragentin adı]],Table2[Kontragentin adı],Table2[Müqavilə nömrəsi],"Xəta",0) -> 0 | M30: =_xlfn.XLOOKUP(Table4[[#This Row],[Kontragentin adı]],Table2[Kontragentin adı],Table2[Müqavilə nömrəsi],"Xəta",0) -> 0
B31: =ROW()-3 -> 28 | C31: 46174 | D31: {=_xlfn.XLOOKUP(Table4[[#This Row],[Malın kodu]],Table1[[#All],[Malın kodu]],Table1[[#All],[Malın adı]],"xəta",0)} -> Laboratoriya sınaq qabları / kolba / plastik | E31: 0000009 | F31: dəst | G31: 1 | I31: =Table4[[#This Row],[Malın miqdarı]]*Table4[[#This Row],[Vahidin qiyməti]] -> 0 | J31: Əvvələ qalıq | K31: Anbar qalığı | L31: =_xlfn.XLOOKUP(Table4[[#This Row],[Kontragentin adı]],Table2[Kontragentin adı],Table2[Müqavilə nömrəsi],"Xəta",0) -> 0 | M31: =_xlfn.XLOOKUP(Table4[[#This Row],[Kontragentin adı]],Table2[Kontragentin adı],Table2[Müqavilə nömrəsi],"Xəta",0) -> 0
B32: =ROW()-3 -> 29 | C32: 46174 | D32: {=_xlfn.XLOOKUP(Table4[[#This Row],[Malın kodu]],Table1[[#All],[Malın kodu]],Table1[[#All],[Malın adı]],"xəta",0)} -> Filtr/ yanacaq/ PL 270 / "SCT" / Turbomax | E32: 0000010 | F32: ədəd | G32: 1 | I32: =Table4[[#This Row],[Malın miqdarı]]*Table4[[#This Row],[Vahidin qiyməti]] -> 0 | J32: Əvvələ qalıq | K32: Anbar qalığı | L32: =_xlfn.XLOOKUP(Table4[[#This Row],[Kontragentin adı]],Table2[Kontragentin adı],Table2[Müqavilə nömrəsi],"Xəta",0) -> 0 | M32: =_xlfn.XLOOKUP(Table4[[#This Row],[Kontragentin adı]],Table2[Kontragentin adı],Table2[Müqavilə nömrəsi],"Xəta",0) -> 0
B33: =ROW()-3 -> 30 | C33: 46174 | D33: {=_xlfn.XLOOKUP(Table4[[#This Row],[Malın kodu]],Table1[[#All],[Malın kodu]],Table1[[#All],[Malın adı]],"xəta",0)} -> Filtr/ yanacaq/ ZP3043 FMB/ "FİL"/Türkiyə istehsalı | E33: 0000011 | F33: ədəd | G33: 2 | I33: =Table4[[#This Row],[Malın miqdarı]]*Table4[[#This Row],[Vahidin qiyməti]] -> 0 | J33: Əvvələ qalıq | K33: Anbar qalığı | L33: =_xlfn.XLOOKUP(Table4[[#This Row],[Kontragentin adı]],Table2[Kontragentin adı],Table2[Müqavilə nömrəsi],"Xəta",0) -> 0 | M33: =_xlfn.XLOOKUP(Table4[[#This Row],[Kontragentin adı]],Table2[Kontragentin adı],Table2[Müqavilə nömrəsi],"Xəta",0) -> 0
B34: =ROW()-3 -> 31 | C34: 46174 | D34: {=_xlfn.XLOOKUP(Table4[[#This Row],[Malın kodu]],Table1[[#All],[Malın kodu]],Table1[[#All],[Malın adı]],"xəta",0)} -> Filtr/ yağ/ ZP531/ "FİL"/Türkiyə istehsalı | E34: 0000012 | F34: ədəd | G34: 1 | I34: =Table4[[#This Row],[Malın miqdarı]]*Table4[[#This Row],[Vahidin qiyməti]] -> 0 | J34: Əvvələ qalıq | K34: Anbar qalığı | L34: =_xlfn.XLOOKUP(Table4[[#This Row],[Kontragentin adı]],Table2[Kontragentin adı],Table2[Müqavilə nömrəsi],"Xəta",0) -> 0 | M34: =_xlfn.XLOOKUP(Table4[[#This Row],[Kontragentin adı]],Table2[Kontragentin adı],Table2[Müqavilə nömrəsi],"Xəta",0) -> 0
... B983: =ROW()-3 -> 980 | C983: 46174 | D983: {=_xlfn.XLOOKUP(Table4[[#This Row],[Malın kodu]],Table1[[#All],[Malın kodu]],Table1[[#All],[Malın adı]],"xəta",0)} -> Planşet / taxeometr üçün | E983: 0001075 | F983: ədəd | G983: 1 | I983: =Table4[[#This Row],[Malın miqdarı]]*Table4[[#This Row],[Vahidin qiyməti]] -> 0 | J983: Əvvələ qalıq | K983: Anbar qalığı | L983: =_xlfn.XLOOKUP(Table4[[#This Row],[Kontragentin adı]],Table2[Kontragentin adı],Table2[Müqavilə nömrəsi],"Xəta",0) -> 0 | M983: =_xlfn.XLOOKUP(Table4[[#This Row],[Kontragentin adı]],Table2[Kontragentin adı],Table2[Müqavilə nömrəsi],"Xəta",0) -> 0
B984: =ROW()-3 -> 981 | C984: 46179 | D984: {=_xlfn.XLOOKUP(Table4[[#This Row],[Malın kodu]],Table1[[#All],[Malın kodu]],Table1[[#All],[Malın adı]],"xəta",0)} -> Mouse-Keyboard / wireless / "DELL" KM3322W | E984: 0000966 | F984: dəst | G984: 1 | H984: 57.5 | I984: =Table4[[#This Row],[Malın miqdarı]]*Table4[[#This Row],[Vahidin qiyməti]] -> 57.5 | J984: Köçürmə | K984: "PROCOMP" MMC | L984: №050626-1 | M984: =_xlfn.XLOOKUP(Table4[[#This Row],[Kontragentin adı]],Table2[Kontragentin adı],Table2[Müqavilə nömrəsi],"Xəta",0) -> №050626-1
B985: =ROW()-3 -> 982 | C985: 46179 | D985: {=_xlfn.XLOOKUP(Table4[[#This Row],[Malın kodu]],Table1[[#All],[Malın kodu]],Table1[[#All],[Malın adı]],"xəta",0)} -> Notebook / 16GB / 512GB / SSD 6GB / "HP" VİCTUS 15-FA2082 WM i5-1342OH | E985: 0000967 | F985: ədəd | G985: 1 | H985: 1737 | I985: =Table4[[#This Row],[Malın miqdarı]]*Table4[[#This Row],[Vahidin qiyməti]] -> 1737 | J985: Köçürmə | K985: "PROCOMP" MMC | L985: №050626-1 | M985: =_xlfn.XLOOKUP(Table4[[#This Row],[Kontragentin adı]],Table2[Kontragentin adı],Table2[Müqavilə nömrəsi],"Xəta",0) -> №050626-1
B986: =ROW()-3 -> 983 | C986: 46179 | D986: {=_xlfn.XLOOKUP(Table4[[#This Row],[Malın kodu]],Table1[[#All],[Malın kodu]],Table1[[#All],[Malın adı]],"xəta",0)} -> Çanta / notebook üçün / "HP" Prelude 15.6" TOP LOAD | E986: 0000968 | F986: ədəd | G986: 1 | H986: 39.8 | I986: =Table4[[#This Row],[Malın miqdarı]]*Table4[[#This Row],[Vahidin qiyməti]] -> 39.8 | J986: Köçürmə | K986: "PROCOMP" MMC | L986: №050626-1 | M986: =_xlfn.XLOOKUP(Table4[[#This Row],[Kontragentin adı]],Table2[Kontragentin adı],Table2[Müqavilə nömrəsi],"Xəta",0) -> №050626-1
B987: =ROW()-3 -> 984 | C987: 46181 | D987: {=_xlfn.XLOOKUP(Table4[[#This Row],[Malın kodu]],Table1[[#All],[Malın kodu]],Table1[[#All],[Malın adı]],"xəta",0)} -> Burğu / 8 x 120 mm | E987: 0000219 | F987: ədəd | G987: 1 | H987: 1 | I987: =Table4[[#This Row],[Malın miqdarı]]*Table4[[#This Row],[Vahidin qiyməti]] -> 1 | J987: Köçürmə | K987: "Neq MMC" | L987: =_xlfn.XLOOKUP(Table4[[#This Row],[Kontragentin adı]],Table2[Kontragentin adı],Table2[Müqavilə nömrəsi],"Xəta",0) -> № 24-060 | M987: 4466
B988: =ROW()-3 -> 985 | C988: 46181 | D988: {=_xlfn.XLOOKUP(Table4[[#This Row],[Malın kodu]],Table1[[#All],[Malın kodu]],Table1[[#All],[Malın adı]],"xəta",0)} -> Valik / 20-lik "Defne" | E988: 0000993 | F988: ədəd | G988: 5 | H988: 1.7 | I988: =Table4[[#This Row],[Malın miqdarı]]*Table4[[#This Row],[Vahidin qiyməti]] -> 8.5 | J988: Köçürmə | K988: "Neq MMC" | L988: =_xlfn.XLOOKUP(Table4[[#This Row],[Kontragentin adı]],Table2[Kontragentin adı],Table2[Müqavilə nömrəsi],"Xəta",0) -> № 24-060 | M988: 4466
B989: =ROW()-3 -> 986 | C989: 46181 | D989: {=_xlfn.XLOOKUP(Table4[[#This Row],[Malın kodu]],Table1[[#All],[Malın kodu]],Table1[[#All],[Malın adı]],"xəta",0)} -> Qaynaq çubuğu (elektrod) / 3 / "Azkaynak" | E989: 0000995 | F989: paçka | G989: 2 | H989: 16 | I989: =Table4[[#This Row],[Malın miqdarı]]*Table4[[#This Row],[Vahidin qiyməti]] -> 32 | J989: Köçürmə | K989: "Neq MMC" | L989: =_xlfn.XLOOKUP(Table4[[#This Row],[Kontragentin adı]],Table2[Kontragentin adı],Table2[Müqavilə nömrəsi],"Xəta",0) -> № 24-060 | M989: 4466
B990: =ROW()-3 -> 987 | C990: 46181 | D990: {=_xlfn.XLOOKUP(Table4[[#This Row],[Malın kodu]],Table1[[#All],[Malın kodu]],Table1[[#All],[Malın adı]],"xəta",0)} -> Əlcək / sarı | E990: 0000996 | F990: ədəd | G990: 50 | H990: 3.5 | I990: =Table4[[#This Row],[Malın miqdarı]]*Table4[[#This Row],[Vahidin qiyməti]] -> 175 | J990: Köçürmə | K990: "Neq MMC" | L990: =_xlfn.XLOOKUP(Table4[[#This Row],[Kontragentin adı]],Table2[Kontragentin adı],Table2[Müqavilə nömrəsi],"Xəta",0) -> № 24-060 | M990: 4466
B991: =ROW()-3 -> 988 | C991: 46181 | D991: {=_xlfn.XLOOKUP(Table4[[#This Row],[Malın kodu]],Table1[[#All],[Malın kodu]],Table1[[#All],[Malın adı]],"xəta",0)} -> Metrə / 5m | E991: 0001033 | F991: ədəd | G991: 3 | H991: 2 | I991: =Table4[[#This Row],[Malın miqdarı]]*Table4[[#This Row],[Vahidin qiyməti]] -> 6 | J991: Köçürmə | K991: "Neq MMC" | L991: =_xlfn.XLOOKUP(Table4[[#This Row],[Kontragentin adı]],Table2[Kontragentin adı],Table2[Müqavilə nömrəsi],"Xəta",0) -> № 24-060 | M991: 4466
B992: =ROW()-3 -> 989 | C992: 46181 | D992: {=_xlfn.XLOOKUP(Table4[[#This Row],[Malın kodu]],Table1[[#All],[Malın kodu]],Table1[[#All],[Malın adı]],"xəta",0)} -> Metrə / 3m | E992: 0001090 | F992: ədəd | G992: 2 | H992: 1 | I992: =Table4[[#This Row],[Malın miqdarı]]*Table4[[#This Row],[Vahidin qiyməti]] -> 2 | J992: Köçürmə | K992: "Neq MMC" | L992: =_xlfn.XLOOKUP(Table4[[#This Row],[Kontragentin adı]],Table2[Kontragentin adı],Table2[Müqavilə nömrəsi],"Xəta",0) -> № 24-060 | M992: 4466
B993: =ROW()-3 -> 990 | C993: 46181 | D993: {=_xlfn.XLOOKUP(Table4[[#This Row],[Malın kodu]],Table1[[#All],[Malın kodu]],Table1[[#All],[Malın adı]],"xəta",0)} -> Bel sapı | E993: 0001131 | F993: ədəd | G993: 10 | H993: 2 | I993: =Table4[[#This Row],[Malın miqdarı]]*Table4[[#This Row],[Vahidin qiyməti]] -> 20 | J993: Köçürmə | K993: "Neq MMC" | L993: =_xlfn.XLOOKUP(Table4[[#This Row],[Kontragentin adı]],Table2[Kontragentin adı],Table2[Müqavilə nömrəsi],"Xəta",0) -> № 24-060 | M993: 4466
B994: =ROW()-3 -> 991 | C994: 46181 | D994: {=_xlfn.XLOOKUP(Table4[[#This Row],[Malın kodu]],Table1[[#All],[Malın kodu]],Table1[[#All],[Malın adı]],"xəta",0)} -> Jilet / fəhlə | E994: 0001133 | F994: ədəd | G994: 15 | H994: 1.3 | I994: =Table4[[#This Row],[Malın miqdarı]]*Table4[[#This Row],[Vahidin qiyməti]] -> 19.5 | J994: Köçürmə | K994: "Neq MMC" | L994: =_xlfn.XLOOKUP(Table4[[#This Row],[Kontragentin adı]],Table2[Kontragentin adı],Table2[Müqavilə nömrəsi],"Xəta",0) -> № 24-060 | M994: 4466
B995: =ROW()-3 -> 992 | C995: 46181 | D995: {=_xlfn.XLOOKUP(Table4[[#This Row],[Malın kodu]],Table1[[#All],[Malın kodu]],Table1[[#All],[Malın adı]],"xəta",0)} -> Çəkic / 2 kq | E995: 0001148 | F995: ədəd | G995: 1 | H995: 7.5 | I995: =Table4[[#This Row],[Malın miqdarı]]*Table4[[#This Row],[Vahidin qiyməti]] -> 7.5 | J995: Köçürmə | K995: "Neq MMC" | L995: =_xlfn.XLOOKUP(Table4[[#This Row],[Kontragentin adı]],Table2[Kontragentin adı],Table2[Müqavilə nömrəsi],"Xəta",0) -> № 24-060 | M995: 4466
B996: =ROW()-3 -> 993 | C996: 46181 | D996: {=_xlfn.XLOOKUP(Table4[[#This Row],[Malın kodu]],Table1[[#All],[Malın kodu]],Table1[[#All],[Malın adı]],"xəta",0)} -> Disk / d 230mm / nerj nazik | E996: 0001175 | F996: ədəd | G996: 25 | H996: 3.8 | I996: =Table4[[#This Row],[Malın miqdarı]]*Table4[[#This Row],[Vahidin qiyməti]] -> 95 | J996: Köçürmə | K996: "Neq MMC" | L996: =_xlfn.XLOOKUP(Table4[[#This Row],[Kontragentin adı]],Table2[Kontragentin adı],Table2[Müqavilə nömrəsi],"Xəta",0) -> № 24-060 | M996: 4466
...

Sheet Hesabat Anbar
A3: Anbar adı | B3: Malın adı | C3: Malın kodu | D3: Giriş miqdarı | E3: Çıxış miqdarı | F3: Anbar qalığı
A4: Astara | B4: Yağ / transmissiya / 80 W 90 / API GL-5 / 20Litr / "ALPINE" Almaniya istehsalı | C4: 0000430 | D4: 1 | E4: 0 | F4: 1
A5: Astara | B5: Ucluq / mis / DT95 | C5: 0001059 | D5: 20 | E5: 0 | F5: 20
A6: Astara | B6: Tesar/Victaulic bağlantı | C6: 0001144 | D6: 1 | E6: 0 | F6: 1
A7: Astara | B7: TAYRAP / 5x250 / QARA | C7: 0001058 | D7: 10 | E7: 0 | F7: 10
A8: Astara | B8: Su tərəzisi | C8: 0000344 | D8: 1 | E8: 0 | F8: 1
A9: Astara | B9: Su pompası / dalğıc | C9: 0000333 | D9: 1 | E9: 0 | F9: 1
A10: Astara | B10: Su pompası / d 76mm / 6.6 kVt / H 28metr / "Grindex" / 0940147 | C10: 0001231 | D10: 1 | E10: 0 | F10: 1
A11: Astara | B11: Siyirtmə /d 110mm / kürəvi | C11: 0001143 | D11: 1 | E11: 0 | F11: 1
A12: Astara | B12: Projektor / led / 100 Vt / mini | C12: 0001061 | D12: 10 | E12: 0 | F12: 10
A13: Astara | B13: Printer / ağ-qara / skaner ilə / "Epson" / L3251 / Filippin istehsalı | C13: 0000160 | D13: 1 | E13: 0 | F13: 1
A14: Astara | B14: Press 120 | C14: 0001060 | D14: 1 | E14: 0 | F14: 1
A15: Astara | B15: Potric uzatma prizi / 5x32A / 225 | C15: 0001054 | D15: 20 | E15: 0 | F15: 20
... A1332: Xocahəsən | B1332: Açar / krokodil tipli | C1332: 0001202 | D1332: 1 | E1332: 0 | F1332: 1

Sheet Hesabat Filtrasiya
A1: Row Labels | B1: Sum of Malın miqdarı | C1: Sum of Ümumi məbləğ
A2: Anbar qalığı | B2: 8346.75 | C2: 0
A3: Əvvələ qalıq | B3: 8346.75 | C3: 0
A4: "Oyal" MMC | B4: 15 | C4: 38.3
A5: Nağd | B5: 15 | C5: 38.3
A6: "PROCOMP" MMC | B6: 3 | C6: 1834.3
A7: Köçürmə | B7: 3 | C7: 1834.3
A8: "Amper Elektrik" | B8: 367 | C8: 2657.89
A9: Köçürmə | B9: 366 | C9: 2595.89
A10: Nağd | B10: 1 | C10: 62
A11: "Eldost İnşaat" | B11: 98 | C11: 1383.5
A12: "Neq MMC" | B12: 674 | C12: 2145.25
A13: "OMİD" | B13: 19 | C13: 469.39
... A32: Grand Total | B32: 11157.25 | C32: 56917.39

Sheet Ələt (Anbar)
B3: № | C3: Tarix | D3: Malın kodu | E3: Malın adı | F3: Giriş miqdarı | G3: Çıxış miqdarı | H3: Növü | I3: Kontragentin / Layihənin adı
B4: =ROW()-3 -> 1 | C4: 46148 | D4: 0001039 | E4: =_xlfn.XLOOKUP(Table7[[#This Row],[Malın kodu]],Table4[Malın kodu],Table4[Malın adı],"Xəta",0) -> Qıfıl / VAZ | F4: 3 | H4: Satınalma | I4: Kommersiya şirkəti
B5: =ROW()-3 -> 2 | C5: 46148 | D5: 0001040 | E5: =_xlfn.XLOOKUP(Table7[[#This Row],[Malın kodu]],Table4[Malın kodu],Table4[Malın adı],"Xəta",0) -> Qıfıl / Extra 70 | F5: 2 | H5: Satınalma | I5: Kommersiya şirkəti
B6: =ROW()-3 -> 3 | C6: 46148 | D6: 0001041 | E6: =_xlfn.XLOOKUP(Table7[[#This Row],[Malın kodu]],Table4[Malın kodu],Table4[Malın adı],"Xəta",0) -> Projektor / led / 200 Vt | F6: 3 | H6: Satınalma | I6: Kommersiya şirkəti
B7: =ROW()-3 -> 4 | C7: 46148 | D7: 0001042 | E7: =_xlfn.XLOOKUP(Table7[[#This Row],[Malın kodu]],Table4[Malın kodu],Table4[Malın adı],"Xəta",0) -> Lampa / 12 Vt / ağ / kürəvi | F7: 10 | H7: Satınalma | I7: Kommersiya şirkəti
B8: =ROW()-3 -> 5 | C8: 46148 | D8: 0001043 | E8: =_xlfn.XLOOKUP(Table7[[#This Row],[Malın kodu]],Table4[Malın kodu],Table4[Malın adı],"Xəta",0) -> Əlcək / göy | F8: 2 | H8: Satınalma | I8: Kommersiya şirkəti
B9: =ROW()-3 -> 6 | C9: 46148 | D9: 0001044 | E9: =_xlfn.XLOOKUP(Table7[[#This Row],[Malın kodu]],Table4[Malın kodu],Table4[Malın adı],"Xəta",0) -> Metrə / 10m / "Fisko" / N88 | F9: 1 | H9: Satınalma | I9: Kommersiya şirkəti
B10: =ROW()-3 -> 7 | C10: 46148 | D10: 0001045 | E10: =_xlfn.XLOOKUP(Table7[[#This Row],[Malın kodu]],Table4[Malın kodu],Table4[Malın adı],"Xəta",0) -> Araba təkəri | F10: 1 | H10: Satınalma | I10: Kommersiya şirkəti
B11: =ROW()-3 -> 8 | C11: 46174 | D11: 0000001 | E11: =_xlfn.XLOOKUP(Table7[[#This Row],[Malın kodu]],Table4[Malın kodu],Table4[Malın adı],"Xəta",0) -> Filtr/ yağ/ ZP3375 MG/ "FİL"/Türkiyə istehsalı | F11: 1 | H11: Əvvələ qalıq | I11: Əvvələ anbar qalığı
B12: =ROW()-3 -> 9 | C12: 46174 | D12: 0000002 | E12: =_xlfn.XLOOKUP(Table7[[#This Row],[Malın kodu]],Table4[Malın kodu],Table4[Malın adı],"Xəta",0) -> Filtr/ yağ/ ZP520/ "FİL"/Türkiyə istehsalı | F12: 1 | H12: Əvvələ qalıq | I12: Əvvələ anbar qalığı
B13: =ROW()-3 -> 10 | C13: 46174 | D13: 0000003 | E13: =_xlfn.XLOOKUP(Table7[[#This Row],[Malın kodu]],Table4[Malın kodu],Table4[Malın adı],"Xəta",0) -> Kabel qoruyucu gövdə / alüminium / kontaktor üçün | F13: 17 | H13: Əvvələ qalıq | I13: Əvvələ anbar qalığı
B14: =ROW()-3 -> 11 | C14: 46174 | D14: 0000004 | E14: =_xlfn.XLOOKUP(Table7[[#This Row],[Malın kodu]],Table4[Malın kodu],Table4[Malın adı],"Xəta",0) -> Gərginlik sabitləşdiricisi / 1 faza / "ANDELİ" / SVC-200000VA | F14: 1 | H14: Əvvələ qalıq | I14: Əvvələ anbar qalığı
B15: =ROW()-3 -> 12 | C15: 46174 | D15: 0000005 | E15: =_xlfn.XLOOKUP(Table7[[#This Row],[Malın kodu]],Table4[Malın kodu],Table4[Malın adı],"Xəta",0) -> Elektrik lövhə / 550x800mm / metal | F15: 1 | H15: Əvvələ qalıq | I15: Əvvələ anbar qalığı
... B532: =ROW()-3 -> 529 | C532: 46174 | D532: 0000522 | E532: =_xlfn.XLOOKUP(Table7[[#This Row],[Malın kodu]],Table4[Malın kodu],Table4[Malın adı],"Xəta",0) -> Lobzik / elektrik / 500 Vt / GST700 | F532: 1 | H532: Əvvələ qalıq | I532: Əvvələ anbar qalığı
B533: =ROW()-3 -> 530 | C533: 46174 | D533: 0000523 | E533: =_xlfn.XLOOKUP(Table7[[#This Row],[Malın kodu]],Table4[Malın kodu],Table4[Malın adı],"Xəta",0) -> Xəta | H533: Əvvələ qalıq | I533: Əvvələ anbar qalığı
B534: =ROW()-3 -> 531 | C534: 46174 | D534: 0000524 | E534: =_xlfn.XLOOKUP(Table7[[#This Row],[Malın kodu]],Table4[Malın kodu],Table4[Malın adı],"Xəta",0) -> Keçid / d 250 x 280 mm / polietilen / "NTG" / Türkiyə istehsalı | F534: 1 | H534: Əvvələ qalıq | I534: Əvvələ anbar qalığı
B535: =ROW()-3 -> 532 | C535: 46174 | D535: 0000525 | E535: =_xlfn.XLOOKUP(Table7[[#This Row],[Malın kodu]],Table4[Malın kodu],Table4[Malın adı],"Xəta",0) -> Keçid / d 250 x 315 mm / polietilen / "NTG" / Türkiyə istehsalı | F535: 1 | H535: Əvvələ qalıq | I535: Əvvələ anbar qalığı
B536: =ROW()-3 -> 533 | C536: 46174 | D536: 0000526 | E536: =_xlfn.XLOOKUP(Table7[[#This Row],[Malın kodu]],Table4[Malın kodu],Table4[Malın adı],"Xəta",0) -> Dirsək (Угол) / d 350 mm / polietilen / 45° | F536: 1 | H536: Əvvələ qalıq | I536: Əvvələ anbar qalığı
B537: =ROW()-3 -> 534 | C537: 46174 | D537: 0000527 | E537: =_xlfn.XLOOKUP(Table7[[#This Row],[Malın kodu]],Table4[Malın kodu],Table4[Malın adı],"Xəta",0) -> Keçid / d 160 x 280 mm / polietilen | F537: 2 | H537: Əvvələ qalıq | I537: Əvvələ anbar qalığı
B538: =ROW()-3 -> 535 | C538: 46174 | D538: 0000528 | E538: =_xlfn.XLOOKUP(Table7[[#This Row],[Malın kodu]],Table4[Malın kodu],Table4[Malın adı],"Xəta",0) -> Üçlük / d 200 x 280 mm / polietilen | F538: 2 | H538: Əvvələ qalıq | I538: Əvvələ anbar qalığı
B539: =ROW()-3 -> 536 | C539: 46174 | D539: 0000529 | E539: =_xlfn.XLOOKUP(Table7[[#This Row],[Malın kodu]],Table4[Malın kodu],Table4[Malın adı],"Xəta",0) -> Üçlük / d 160 x 225 mm / polietilen | F539: 1 | H539: Əvvələ qalıq | I539: Əvvələ anbar qalığı
B540: =ROW()-3 -> 537 | C540: 46174 | D540: 0000530 | E540: =_xlfn.XLOOKUP(Table7[[#This Row],[Malın kodu]],Table4[Malın kodu],Table4[Malın adı],"Xəta",0) -> Dirsək / d 180 mm / polietilen / 45° / "Borfit" / Türkiyə istehsalı | F540: 1 | H540: Əvvələ qalıq | I540: Əvvələ anbar qalığı
B541: =ROW()-3 -> 538 | C541: 46174 | D541: 0000531 | E541: =_xlfn.XLOOKUP(Table7[[#This Row],[Malın kodu]],Table4[Malın kodu],Table4[Malın adı],"Xəta",0) -> Adaptor / d 110 mm / polietilen / "Borfit" / Türkiyə istehsalı | F541: 3 | H541: Əvvələ qalıq | I541: Əvvələ anbar qalığı
B542: =ROW()-3 -> 539 | C542: 46174 | D542: 0000532 | E542: =_xlfn.XLOOKUP(Table7[[#This Row],[Malın kodu]],Table4[Malın kodu],Table4[Malın adı],"Xəta",0) -> Üçlük / d 160 x 710 mm / polietilen / "Borfit" / Türkiyə istehsalı | F542: 1 | H542: Əvvələ qalıq | I542: Əvvələ anbar qalığı
B543: =ROW()-3 -> 540 | C543: 46174 | D543: 0000533 | E543: =_xlfn.XLOOKUP(Table7[[#This Row],[Malın kodu]],Table4[Malın kodu],Table4[Malın adı],"Xəta",0) -> Üçlük / d 110 x 160 mm / polietilen / "Borfit" / Türkiyə istehsalı | F543: 1 | H543: Əvvələ qalıq | I543: Əvvələ anbar qalığı
B544: =ROW()-3 -> 541 | C544: 46174 | D544: 0000534 | E544: =_xlfn.XLOOKUP(Table7[[#This Row],[Malın kodu]],Table4[Malın kodu],Table4[Malın adı],"Xəta",0) -> Qapaq / d 280 mm / polietilen / "Borfit" / Türkiyə istehsalı | F544: 1 | H544: Əvvələ qalıq | I544: Əvvələ anbar qalığı
B545: =ROW()-3 -> 542 | C545: 46174 | D545: 0000535 | E545: =_xlfn.XLOOKUP(Table7[[#This Row],[Malın kodu]],Table4[Malın kodu],Table4[Malın adı],"Xəta",0) -> Qapaq / d 160 mm / polietilen / "Borfit" / Türkiyə istehsalı | F545: 3 | H545: Əvvələ qalıq | I545: Əvvələ anbar qalığı
... B674: =ROW()-3 -> 671 | C674: 46174 | D674: 0000664 | E674: =_xlfn.XLOOKUP(Table7[[#This Row],[Malın kodu]],Table4[Malın kodu],Table4[Malın adı],"Xəta",0) -> Qapaq / flyanslı / metal / 605x20mm | F674: 5 | H674: Əvvələ qalıq | I674: Əvvələ anbar qalığı
B675: =ROW()-3 -> 672 | C675: 46174 | D675: 0000665 | E675: =_xlfn.XLOOKUP(Table7[[#This Row],[Malın kodu]],Table4[Malın kodu],Table4[Malın adı],"Xəta",0) -> Xəta | H675: Əvvələ qalıq | I675: Əvvələ anbar qalığı
B676: =ROW()-3 -> 673 | C676: 46174 | D676: 0000666 | E676: =_xlfn.XLOOKUP(Table7[[#This Row],[Malın kodu]],Table4[Malın kodu],Table4[Malın adı],"Xəta",0) -> Servis birləşməsi / elektrofizyon / d 110 x 32 mm / "Borfit" / Türkiyə istehsalı | F676: 107 | H676: Əvvələ qalıq | I676: Əvvələ anbar qalığı
B677: =ROW()-3 -> 674 | C677: 46174 | D677: 0000667 | E677: =_xlfn.XLOOKUP(Table7[[#This Row],[Malın kodu]],Table4[Malın kodu],Table4[Malın adı],"Xəta",0) -> Servis birləşməsi / elektrofizyon / d 110 x 40 mm / "Borfit" / Türkiyə istehsalı | F677: 22 | H677: Əvvələ qalıq | I677: Əvvələ anbar qalığı
B678: =ROW()-3 -> 675 | C678: 46174 | D678: 0000668 | E678: =_xlfn.XLOOKUP(Table7[[#This Row],[Malın kodu]],Table4[Malın kodu],Table4[Malın adı],"Xəta",0) -> Servis birləşməsi / elektrofizyon / d 110 x 63 mm / "Borfit" / Türkiyə istehsalı | F678: 6 | H678: Əvvələ qalıq | I678: Əvvələ anbar qalığı
B679: =ROW()-3 -> 676 | C679: 46174 | D679: 0000669 | E679: =_xlfn.XLOOKUP(Table7[[#This Row],[Malın kodu]],Table4[Malın kodu],Table4[Malın adı],"Xəta",0) -> Servis birləşməsi / elektrofizyon / d 63 x 280 mm / "Borfit" / Türkiyə istehsalı | F679: 1 | H679: Əvvələ qalıq | I679: Əvvələ anbar qalığı
B680: =ROW()-3 -> 677 | C680: 46174 | D680: 0000670 | E680: =_xlfn.XLOOKUP(Table7[[#This Row],[Malın kodu]],Table4[Malın kodu],Table4[Malın adı],"Xəta",0) -> Servis birləşməsi / elektrofizyon / d 40 x 280 mm / "Borfit" / Türkiyə istehsalı | F680: 1 | H680: Əvvələ qalıq | I680: Əvvələ anbar qalığı
B681: =ROW()-3 -> 678 | C681: 46174 | D681: 0000671 | E681: =_xlfn.XLOOKUP(Table7[[#This Row],[Malın kodu]],Table4[Malın kodu],Table4[Malın adı],"Xəta",0) -> Servis birləşməsi / elektrofizyon / d 32 x 90 mm / "Borfit" / Türkiyə istehsalı | F681: 1 | H681: Əvvələ qalıq | I681: Əvvələ anbar qalığı
B682: =ROW()-3 -> 679 | C682: 46174 | D682: 0000672 | E682: =_xlfn.XLOOKUP(Table7[[#This Row],[Malın kodu]],Table4[Malın kodu],Table4[Malın adı],"Xəta",0) -> Servis birləşməsi / elektrofizyon / d 32 x 63 mm / "Borfit" / Türkiyə istehsalı | F682: 4 | H682: Əvvələ qalıq | I682: Əvvələ anbar qalığı
B683: =ROW()-3 -> 680 | C683: 46174 | D683: 0000673 | E683: =_xlfn.XLOOKUP(Table7[[#This Row],[Malın kodu]],Table4[Malın kodu],Table4[Malın adı],"Xəta",0) -> Servis birləşməsi / elektrofizyon / d 40 x 63 mm / "Borfit" / Türkiyə istehsalı | F683: 3 | H683: Əvvələ qalıq | I683: Əvvələ anbar qalığı
B684: =ROW()-3 -> 681 | C684: 46174 | D684: 0000674 | E684: =_xlfn.XLOOKUP(Table7[[#This Row],[Malın kodu]],Table4[Malın kodu],Table4[Malın adı],"Xəta",0) -> Servis birləşməsi / elektrofizyon / d 40 x 90 mm / "Borfit" / Türkiyə istehsalı | F684: 2 | H684: Əvvələ qalıq | I684: Əvvələ anbar qalığı
B685: =ROW()-3 -> 682 | C685: 46174 | D685: 0000675 | E685: =_xlfn.XLOOKUP(Table7[[#This Row],[Malın kodu]],Table4[Malın kodu],Table4[Malın adı],"Xəta",0) -> Servis birləşməsi / elektrofizyon / d 32 x 40 mm / "TEGA" / Türkiyə istehsalı | F685: 2 | H685: Əvvələ qalıq | I685: Əvvələ anbar qalığı
B686: =ROW()-3 -> 683 | C686: 46174 | D686: 0000676 | E686: =_xlfn.XLOOKUP(Table7[[#This Row],[Malın kodu]],Table4[Malın kodu],Table4[Malın adı],"Xəta",0) -> Dirsək / d 110 mm / polietilen / 90° | F686: 17 | H686: Əvvələ qalıq | I686: Əvvələ anbar qalığı
...

Sheet Yasamal (Qanlı göl) (Anbar)
B3: № | C3: Tarix | D3: Malın kodu | E3: Malın adı | F3: Giriş miqdarı | G3: Çıxış miqdarı | H3: Növü | I3: Kontragentin / Layihənin adı
B4: =ROW()-3 -> 1 | E4: =_xlfn.XLOOKUP(Table_Yasamal[[#This Row],[Malın kodu]],Table4[Malın kodu],Table4[Malın adı],"Xəta",0) -> Xəta

Sheet Astara (Anbar)
B3: № | C3: Tarix | D3: Malın kodu | E3: Malın adı | F3: Giriş miqdarı | G3: Çıxış miqdarı | H3: Növü | I3: Kontragentin / Layihənin adı
B4: =ROW()-3 -> 1 | C4: 46148 | D4: 0000997 | E4: =_xlfn.XLOOKUP(Table79[[#This Row],[Malın kodu]],Filtrasiya!E:E,Filtrasiya!D:D,"xəta",0) -> Fırça / N143 (şotka pas qara) | F4: 3 | H4: Satınalma | I4: Kommersiya şirkəti
B5: =ROW()-3 -> 2 | C5: 46148 | D5: 0001038 | E5: =_xlfn.XLOOKUP(Table79[[#This Row],[Malın kodu]],Filtrasiya!E:E,Filtrasiya!D:D,"xəta",0) -> Bıçaq / oboy / N115 | F5: 2 | H5: Satınalma | I5: Kommersiya şirkəti
B6: =ROW()-3 -> 3 | C6: 46148 | D6: 0001046 | E6: =_xlfn.XLOOKUP(Table79[[#This Row],[Malın kodu]],Filtrasiya!E:E,Filtrasiya!D:D,"xəta",0) -> Kömür / laqonda üçün / "Conan" | F6: 1 | H6: Satınalma | I6: Kommersiya şirkəti
B7: =ROW()-3 -> 4 | C7: 46149 | D7: 0001054 | E7: =_xlfn.XLOOKUP(Table79[[#This Row],[Malın kodu]],Filtrasiya!E:E,Filtrasiya!D:D,"xəta",0) -> Potric uzatma prizi / 5x32A / 225 | F7: 20 | H7: Satınalma | I7: Kommersiya şirkəti
B8: =ROW()-3 -> 5 | C8: 46149 | D8: 0001055 | E8: =_xlfn.XLOOKUP(Table79[[#This Row],[Malın kodu]],Filtrasiya!E:E,Filtrasiya!D:D,"xəta",0) -> MİQRİK XCK-J108 POTRİC | F8: 4 | H8: Satınalma | I8: Kommersiya şirkəti
B9: =ROW()-3 -> 6 | C9: 46149 | D9: 0001056 | E9: =_xlfn.XLOOKUP(Table79[[#This Row],[Malın kodu]],Filtrasiya!E:E,Filtrasiya!D:D,"xəta",0) -> Kabel / 2x2.5 / NEXANS H07VV-F 0,6/1 KV | F9: 100 | H9: Satınalma | I9: Kommersiya şirkəti
B10: =ROW()-3 -> 7 | C10: 46149 | D10: 0001057 | E10: =_xlfn.XLOOKUP(Table79[[#This Row],[Malın kodu]],Filtrasiya!E:E,Filtrasiya!D:D,"xəta",0) -> Kabel / 2x4 / NEXANS H07VV-F 0,6/1 KV | F10: 100 | H10: Satınalma | I10: Kommersiya şirkəti
B11: =ROW()-3 -> 8 | C11: 46149 | D11: 0001058 | E11: =_xlfn.XLOOKUP(Table79[[#This Row],[Malın kodu]],Filtrasiya!E:E,Filtrasiya!D:D,"xəta",0) -> TAYRAP / 5x250 / QARA | F11: 10 | H11: Satınalma | I11: Kommersiya şirkəti
B12: =ROW()-3 -> 9 | C12: 46149 | D12: 0001059 | E12: =_xlfn.XLOOKUP(Table79[[#This Row],[Malın kodu]],Filtrasiya!E:E,Filtrasiya!D:D,"xəta",0) -> Ucluq / mis / DT95 | F12: 20 | H12: Satınalma | I12: Kommersiya şirkəti
B13: =ROW()-3 -> 10 | C13: 46149 | D13: 0001060 | E13: =_xlfn.XLOOKUP(Table79[[#This Row],[Malın kodu]],Filtrasiya!E:E,Filtrasiya!D:D,"xəta",0) -> Press 120 | F13: 1 | H13: Satınalma | I13: Kommersiya şirkəti
B14: =ROW()-3 -> 11 | C14: 46149 | D14: 0001061 | E14: =_xlfn.XLOOKUP(Table79[[#This Row],[Malın kodu]],Filtrasiya!E:E,Filtrasiya!D:D,"xəta",0) -> Projektor / led / 100 Vt / mini | F14: 10 | H14: Satınalma | I14: Kommersiya şirkəti
B15: =ROW()-3 -> 12 | C15: 46149 | D15: 0001062 | E15: =_xlfn.XLOOKUP(Table79[[#This Row],[Malın kodu]],Filtrasiya!E:E,Filtrasiya!D:D,"xəta",0) -> Potric / 5x32A / FİŞ 025 | F15: 20 | H15: Satınalma | I15: Kommersiya şirkəti
... B41: =ROW()-3 -> 38 | C41: 46216 | D41: 0000986 | E41: =_xlfn.XLOOKUP(Table79[[#This Row],[Malın kodu]],Filtrasiya!E:E,Filtrasiya!D:D,"xəta",0) -> Jilet / sarı-narıncı / briqadir üçün | F41: 1 | H41: Yerdəyişmə | I41: Ələt anbar
B42: =ROW()-3 -> 39 | C42: 46198 | D42: 0000610 | E42: =_xlfn.XLOOKUP(Table79[[#This Row],[Malın kodu]],Filtrasiya!E:E,Filtrasiya!D:D,"xəta",0) -> Generator / 7.5 kvt / benzin / 220-230V / "KEMAN" / Çin istehsalı | G42: 1 | H42: Yerdəyişmə | I42: Xocahəsən anbar
B43: =ROW()-3 -> 40 | C43: 46174 | D43: 0001229 | E43: =_xlfn.XLOOKUP(Table79[[#This Row],[Malın kodu]],Filtrasiya!E:E,Filtrasiya!D:D,"xəta",0) -> Generator / 205 kVA / "Genpower" | F43: 1 | I43: Əvvələ anbar qalığı
B44: =ROW()-3 -> 41 | C44: 46226 | D44: 0001230 | E44: =_xlfn.XLOOKUP(Table79[[#This Row],[Malın kodu]],Filtrasiya!E:E,Filtrasiya!D:D,"xəta",0) -> Karot ucu / perforator üçün / 40mm | F44: 1 | H44: Satınalma | I44: Nağd alış
B45: =ROW()-3 -> 42 | C45: 46226 | D45: 0001231 | E45: =_xlfn.XLOOKUP(Table79[[#This Row],[Malın kodu]],Filtrasiya!E:E,Filtrasiya!D:D,"xəta",0) -> Su pompası / d 76mm / 6.6 kVt / H 28metr / "Grindex" / 0940147 | F45: 1 | H45: Satınalma | I45: Nağd alış

Sheet Ofis (Anbar)
B3: № | C3: Tarix | D3: Malın kodu | E3: Malın adı | F3: Giriş miqdarı | G3: Çıxış miqdarı | H3: Növü | I3: Kontragentin / Layihənin adı
B4: =ROW()-3 -> 1 | E4: =_xlfn.XLOOKUP(Table_Ofis[[#This Row],[Malın kodu]],Filtrasiya!E:E,Filtrasiya!D:D,"xəta",0) -> 0

Sheet Xocahəsən (Anbar)
B3: № | C3: Tarix | D3: Malın kodu | E3: Malın adı | F3: Giriş miqdarı | G3: Çıxış miqdarı | H3: Növü | I3: Kontragentin / Layihənin adı
B4: =ROW()-3 -> 1 | C4: 46174 | D4: 0001016 | E4: =_xlfn.XLOOKUP(Table7912[[#This Row],[Malın kodu]],Filtrasiya!E:E,Filtrasiya!D:D,"xəta",0) -> Generator / dizel / 50 kvA / "Genpower" | F4: 1 | H4: Əvvələ qalıq | I4: Əvvələ anbar qalığı
B5: =ROW()-3 -> 2 | C5: 46179 | D5: 0000966 | E5: =_xlfn.XLOOKUP(Table7912[[#This Row],[Malın kodu]],Filtrasiya!E:E,Filtrasiya!D:D,"xəta",0) -> Mouse-Keyboard / wireless / "DELL" KM3322W | F5: 1 | H5: Satınalma | I5: Kommersiya şirkəti
B6: =ROW()-3 -> 3 | C6: 46179 | D6: 0000967 | E6: =_xlfn.XLOOKUP(Table7912[[#This Row],[Malın kodu]],Filtrasiya!E:E,Filtrasiya!D:D,"xəta",0) -> Notebook / 16GB / 512GB / SSD 6GB / "HP" VİCTUS 15-FA2082 WM i5-1342OH | F6: 1 | H6: Satınalma | I6: Kommersiya şirkəti
B7: =ROW()-3 -> 4 | C7: 46179 | D7: 0000968 | E7: =_xlfn.XLOOKUP(Table7912[[#This Row],[Malın kodu]],Filtrasiya!E:E,Filtrasiya!D:D,"xəta",0) -> Çanta / notebook üçün / "HP" Prelude 15.6" TOP LOAD | F7: 1 | H7: Satınalma | I7: Kommersiya şirkəti
B8: =ROW()-3 -> 5 | C8: 46181 | D8: 0000219 | E8: =_xlfn.XLOOKUP(Table7912[[#This Row],[Malın kodu]],Filtrasiya!E:E,Filtrasiya!D:D,"xəta",0) -> Burğu / 8 x 120 mm | F8: 1 | H8: Satınalma | I8: Kommersiya şirkəti
B9: =ROW()-3 -> 6 | C9: 46181 | D9: 0000341 | E9: =_xlfn.XLOOKUP(Table7912[[#This Row],[Malın kodu]],Filtrasiya!E:E,Filtrasiya!D:D,"xəta",0) -> Akkumulyator / 12V / 77AH / 640A / "Tungstone" | F9: 1 | H9: Yerdəyişmə | I9: Ələt anbar
B10: =ROW()-3 -> 7 | C10: 46181 | D10: 0000993 | E10: =_xlfn.XLOOKUP(Table7912[[#This Row],[Malın kodu]],Filtrasiya!E:E,Filtrasiya!D:D,"xəta",0) -> Valik / 20-lik "Defne" | F10: 5 | H10: Satınalma | I10: Kommersiya şirkəti
B11: =ROW()-3 -> 8 | C11: 46181 | D11: 0000995 | E11: =_xlfn.XLOOKUP(Table7912[[#This Row],[Malın kodu]],Filtrasiya!E:E,Filtrasiya!D:D,"xəta",0) -> Qaynaq çubuğu (elektrod) / 3 / "Azkaynak" | F11: 2 | H11: Satınalma | I11: Kommersiya şirkəti
B12: =ROW()-3 -> 9 | C12: 46181 | D12: 0000996 | E12: =_xlfn.XLOOKUP(Table7912[[#This Row],[Malın kodu]],Filtrasiya!E:E,Filtrasiya!D:D,"xəta",0) -> Əlcək / sarı | F12: 50 | H12: Satınalma | I12: Kommersiya şirkəti
B13: =ROW()-3 -> 10 | C13: 46181 | D13: 0001033 | E13: =_xlfn.XLOOKUP(Table7912[[#This Row],[Malın kodu]],Filtrasiya!E:E,Filtrasiya!D:D,"xəta",0) -> Metrə / 5m | F13: 3 | H13: Satınalma | I13: Kommersiya şirkəti
B14: =ROW()-3 -> 11 | C14: 46181 | D14: 0001090 | E14: =_xlfn.XLOOKUP(Table7912[[#This Row],[Malın kodu]],Filtrasiya!E:E,Filtrasiya!D:D,"xəta",0) -> Metrə / 3m | F14: 2 | H14: Satınalma | I14: Kommersiya şirkəti
B15: =ROW()-3 -> 12 | C15: 46181 | D15: 0001131 | E15: =_xlfn.XLOOKUP(Table7912[[#This Row],[Malın kodu]],Filtrasiya!E:E,Filtrasiya!D:D,"xəta",0) -> Bel sapı | F15: 10 | H15: Satınalma | I15: Kommersiya şirkəti
... B154: =ROW()-3 -> 151 | C154: 46203 | D154: 0001076 | E154: =_xlfn.XLOOKUP(Table7912[[#This Row],[Malın kodu]],Filtrasiya!E:E,Filtrasiya!D:D,"xəta",0) -> Metal lövhə / 20 mm / 1500x6000 / Cт3сп | F154: 5 | H154: Satınalma | I154: Kommersiya şirkəti
B155: =ROW()-3 -> 152 | C155: 46203 | D155: 0001076 | E155: =_xlfn.XLOOKUP(Table7912[[#This Row],[Malın kodu]],Filtrasiya!E:E,Filtrasiya!D:D,"xəta",0) -> Metal lövhə / 20 mm / 1500x6000 / Cт3сп | G155: 5 | H155: Silinmə | I155: Sahə üzrə məsul şəxs
B156: =ROW()-3 -> 153 | C156: 46203 | D156: 0001084 | E156: =_xlfn.XLOOKUP(Table7912[[#This Row],[Malın kodu]],Filtrasiya!E:E,Filtrasiya!D:D,"xəta",0) -> Bitum / Azmas | F156: 2 | H156: Satınalma | I156: Nağd alış
B157: =ROW()-3 -> 154 | C157: 46203 | D157: 0001085 | E157: =_xlfn.XLOOKUP(Table7912[[#This Row],[Malın kodu]],Filtrasiya!E:E,Filtrasiya!D:D,"xəta",0) -> Stepler / 14 | F157: 1 | H157: Satınalma | I157: Nağd alış
B158: =ROW()-3 -> 155 | C158: 46203 | D158: 0001086 | E158: =_xlfn.XLOOKUP(Table7912[[#This Row],[Malın kodu]],Filtrasiya!E:E,Filtrasiya!D:D,"xəta",0) -> Stepler simi / 14 | F158: 1 | H158: Satınalma | I158: Nağd alış
B159: =ROW()-3 -> 156 | C159: 46203 | D159: 0001087 | E159: =_xlfn.XLOOKUP(Table7912[[#This Row],[Malın kodu]],Filtrasiya!E:E,Filtrasiya!D:D,"xəta",0) -> Silikon | F159: 1 | H159: Satınalma | I159: Nağd alış
B160: =ROW()-3 -> 157 | C160: 46203 | D160: 0001088 | E160: =_xlfn.XLOOKUP(Table7912[[#This Row],[Malın kodu]],Filtrasiya!E:E,Filtrasiya!D:D,"xəta",0) -> Silikon tapancası | F160: 1 | H160: Satınalma | I160: Nağd alış
B161: =ROW()-3 -> 158 | C161: 46203 | D161: 0001089 | E161: =_xlfn.XLOOKUP(Table7912[[#This Row],[Malın kodu]],Filtrasiya!E:E,Filtrasiya!D:D,"xəta",0) -> Yapışdırıcı / kontakt | F161: 1 | H161: Satınalma | I161: Nağd alış
B162: =ROW()-3 -> 159 | C162: 46203 | D162: 0001090 | E162: =_xlfn.XLOOKUP(Table7912[[#This Row],[Malın kodu]],Filtrasiya!E:E,Filtrasiya!D:D,"xəta",0) -> Metrə / 3m | F162: 1 | H162: Satınalma | I162: Nağd alış
B163: =ROW()-3 -> 160 | C163: 46203 | D163: 0001091 | E163: =_xlfn.XLOOKUP(Table7912[[#This Row],[Malın kodu]],Filtrasiya!E:E,Filtrasiya!D:D,"xəta",0) -> Təbaşir | F163: 1 | H163: Satınalma | I163: Nağd alış
B164: =ROW()-3 -> 161 | C164: 46209 | D164: 0001084 | E164: =_xlfn.XLOOKUP(Table7912[[#This Row],[Malın kodu]],Filtrasiya!E:E,Filtrasiya!D:D,"xəta",0) -> Bitum / Azmas | F164: 1 | H164: Satınalma | I164: Nağd alış
B165: =ROW()-3 -> 162 | C165: 46210 | D165: 0001142 | E165: =_xlfn.XLOOKUP(Table7912[[#This Row],[Malın kodu]],Filtrasiya!E:E,Filtrasiya!D:D,"xəta",0) -> Sututucu bant / AK 20/2 | F165: 80 | H165: Satınalma | I165: Kommersiya şirkəti
B166: =ROW()-3 -> 163 | C166: 46211 | D166: 0000993 | E166: =_xlfn.XLOOKUP(Table7912[[#This Row],[Malın kodu]],Filtrasiya!E:E,Filtrasiya!D:D,"xəta",0) -> Valik / 20-lik "Defne" | F166: 5 | H166: Satınalma | I166: Kommersiya şirkəti
B167: =ROW()-3 -> 164 | C167: 46211 | D167: 0000995 | E167: =_xlfn.XLOOKUP(Table7912[[#This Row],[Malın kodu]],Filtrasiya!E:E,Filtrasiya!D:D,"xəta",0) -> Qaynaq çubuğu (elektrod) / 3 / "Azkaynak" | F167: 4 | H167: Satınalma | I167: Kommersiya şirkəti
... B259: =ROW()-3 -> 256 | C259: 46198 | D259: 0000610 | E259: =_xlfn.XLOOKUP(Table7912[[#This Row],[Malın kodu]],Filtrasiya!E:E,Filtrasiya!D:D,"xəta",0) -> Generator / 7.5 kvt / benzin / 220-230V / "KEMAN" / Çin istehsalı | F259: 1 | H259: Yerdəyişmə | I259: Astara

Sheet Nomenklatura bazası
B2: № | C2: Malın adı | D2: Malın kodu | E2: Təkrarlanma
B3: =ROW()-2 -> 1 | C3: Filtr/ yağ/ ZP3375 MG/ "FİL"/Türkiyə istehsalı | D3: =TEXT(ROW()-2,"0000000") -> 0000001 | E3: =COUNTIF(Table1[Malın adı],Table1[[#This Row],[Malın adı]]) -> 1
B4: =ROW()-2 -> 2 | C4: Filtr/ yağ/ ZP520/ "FİL"/Türkiyə istehsalı | D4: =TEXT(ROW()-2,"0000000") -> 0000002 | E4: =COUNTIF(Table1[Malın adı],Table1[[#This Row],[Malın adı]]) -> 1
B5: =ROW()-2 -> 3 | C5: Kabel qoruyucu gövdə / alüminium / kontaktor üçün | D5: =TEXT(ROW()-2,"0000000") -> 0000003 | E5: =COUNTIF(Table1[Malın adı],Table1[[#This Row],[Malın adı]]) -> 1
B6: =ROW()-2 -> 4 | C6: Gərginlik sabitləşdiricisi / 1 faza / "ANDELİ" / SVC-200000VA | D6: =TEXT(ROW()-2,"0000000") -> 0000004 | E6: =COUNTIF(Table1[Malın adı],Table1[[#This Row],[Malın adı]]) -> 1
B7: =ROW()-2 -> 5 | C7: Elektrik lövhə / 550x800mm / metal | D7: =TEXT(ROW()-2,"0000000") -> 0000005 | E7: =COUNTIF(Table1[Malın adı],Table1[[#This Row],[Malın adı]]) -> 1
B8: =ROW()-2 -> 6 | C8: Kabel qoruyucu gövdə / alüminium / kontaktor ilə | D8: =TEXT(ROW()-2,"0000000") -> 0000006 | E8: =COUNTIF(Table1[Malın adı],Table1[[#This Row],[Malın adı]]) -> 1
B9: =ROW()-2 -> 7 | C9: Filtr/ yağ/ ZP540 A/ "FİL"/Türkiyə istehsalı | D9: =TEXT(ROW()-2,"0000000") -> 0000007 | E9: =COUNTIF(Table1[Malın adı],Table1[[#This Row],[Malın adı]]) -> 1
B10: =ROW()-2 -> 8 | C10: Laboratoriya sınaq qabları / podnos tipli / paslanmaz metal | D10: =TEXT(ROW()-2,"0000000") -> 0000008 | E10: =COUNTIF(Table1[Malın adı],Table1[[#This Row],[Malın adı]]) -> 1
B11: =ROW()-2 -> 9 | C11: Laboratoriya sınaq qabları / kolba / plastik | D11: =TEXT(ROW()-2,"0000000") -> 0000009 | E11: =COUNTIF(Table1[Malın adı],Table1[[#This Row],[Malın adı]]) -> 1
B12: =ROW()-2 -> 10 | C12: Filtr/ yanacaq/ PL 270 / "SCT" / Turbomax | D12: =TEXT(ROW()-2,"0000000") -> 0000010 | E12: =COUNTIF(Table1[Malın adı],Table1[[#This Row],[Malın adı]]) -> 1
B13: =ROW()-2 -> 11 | C13: Filtr/ yanacaq/ ZP3043 FMB/ "FİL"/Türkiyə istehsalı | D13: =TEXT(ROW()-2,"0000000") -> 0000011 | E13: =COUNTIF(Table1[Malın adı],Table1[[#This Row],[Malın adı]]) -> 1
B14: =ROW()-2 -> 12 | C14: Filtr/ yağ/ ZP531/ "FİL"/Türkiyə istehsalı | D14: =TEXT(ROW()-2,"0000000") -> 0000012 | E14: =COUNTIF(Table1[Malın adı],Table1[[#This Row],[Malın adı]]) -> 1
... B1233: =ROW()-2 -> 1231 | C1233: Su pompası / d 76mm / 6.6 kVt / H 28metr / "Grindex" / 0940147 | D1233: =TEXT(ROW()-2,"0000000") -> 0001231 | E1233: =COUNTIF(Table1[Malın adı],Table1[[#This Row],[Malın adı]]) -> 1

Sheet Kontragent bazası
B2: № | C2: VÖEN | D2: Kontragentin adı | E2: Qaimə nömrəsi | F2: Müqavilə nömrəsi | G2: Müqavilə tarixi
B3: =ROW()-2 -> 1 | D3: "Ağa İnşat"
B4: =ROW()-2 -> 2 | C4: 1803674831 | D4: "Amper Elektrik" | F4: №198AMP/2026. | G4: 29.04.2026
B5: =ROW()-2 -> 3 | C5: 1803106631 | D5: "Eldost İnşaat" | F5: №72/2026 | G5: 17.06.2026
B6: =ROW()-2 -> 4 | D6: "Əli inşaat"
B7: =ROW()-2 -> 5 | C7: 1700767721 | D7: "HEMAT TRADE" MMC | F7: № 26-052 | G7: 46147
B8: =ROW()-2 -> 6 | C8: 6000261802 | D8: "Həmidov Kamran" | F8: №M08077/26 | G8: 08.06.2026
B9: =ROW()-2 -> 7 | D9: "İronavto"
B10: =ROW()-2 -> 8 | D10: "MAGNA"
B11: =ROW()-2 -> 9 | C11: 2101064132 | D11: "Məhərrəmov Calal" | F11: TSN/XH/SA/07-26/006 | G11: 20.07.2026
B12: =ROW()-2 -> 10 | C12: 1404208661 | D12: "Neq MMC" | F12: № 24-060 | G12: 45611
B13: =ROW()-2 -> 11 | C13: 1504919047 | D13: "OMİD" | G13: 17.06.2026
B14: =ROW()-2 -> 12 | C14: 3333333333 | D14: "Oyal" MMC | F14: OY-215/37 | G14: 46178
B15: =ROW()-2 -> 13 | C15: 1506423331 | D15: "PROCOMP" MMC | F15: №050626-1 | G15: 46178
B16: =ROW()-2 -> 14 | C16: 2222222222 | D16: "Sabiroğlu" MMC | F16: LG-150/26 | G16: 46177
B17: =ROW()-2 -> 15 | D17: "Sontech Groupe"
B18: =ROW()-2 -> 16 | C18: 1101146872 | D18: "Taleh" | F18: №06/2026 | G18: 18.06.2026
B19: =ROW()-2 -> 17 | C19: 2000250161 | D19: "TURQUOİSE" MMC | F19: №21 | G19: 2026
B20: =ROW()-2 -> 18 | C20: 1111111111 | D20: Anbar qalığı | G20: 46174
B21: =ROW()-2 -> 19 | D21: Bazar
B22: =ROW()-2 -> 20 | D22: "Almet-Stp" MMC

Sheet Layihə anbarlarının siyahısı
B2: № | C2: Anbar / Şirkət
B3: =ROW()-2 -> 1 | C3: Ələt anbar
B4: =ROW()-2 -> 2 | C4: Xocahəsən anbar
B5: =ROW()-2 -> 3 | C5: Astara anbar
B6: =ROW()-2 -> 4 | C6: Kommersiya şirkəti
B7: =ROW()-2 -> 5 | C7: Sahə üzrə məsul şəxs
B8: =ROW()-2 -> 6 | C8: Nağd alış
B9: =ROW()-2 -> 7 | C9: Əvvələ anbar qalığı
